fn called with input
err called with input
fn output
[Error: fail]
