fn called with input
err called with input
fn output
error: [Error: fail]
