fn called with input
err called with input
fn called with input
err called with input
fn output
error is [Error: fail]
output is fn output
error is [Error: fail]
